Workbook

Sheet Data Info
A1: Days | B1: Days Number | C1: Weekend/day
A2: Monday | B2: {=SEQUENCE(7,1)} -> 1 | C2: Weekday
A3: Tuesday | B3: 2 | C3: Weekday
A4: Wednesday | B4: 3 | C4: Weekday
A5: Thursday | B5: 4 | C5: Weekday
A6: Friday | B6: 5 | C6: Weekday
A7: Saturday | B7: 6 | C7: Weekend
A8: Sunday | B8: 7 | C8: Weekend
A10: Months | B10: Months Number
A11: January | B11: {=SEQUENCE(12,1)} -> 1
A12: February | B12: 2
A13: March | B13: 3
A14: April | B14: 4
A15: May | B15: 5
A16: June | B16: 6
A17: July | B17: 7
A18: August | B18: 8
A19: September | B19: 9
A20: October | B20: 10
A21: November | B21: 11
A22: December | B22: 12

Sheet Raw Data
A1: Date,Receipt number,Receipt type,Category,SKU,Item,Variant,Modifiers applied,Quantity,Gross sales,Discounts,Net sales,Cost of goods,Gross profit,Taxes,Dining option,POS,Store,Cashier name,Customer name,Customer contacts,Comment,Status | B1: =IFERROR(__xludf.DUMMYFUNCTION("SPLIT(A1,"","")"),"Date") -> Date | C1: =IFERROR(__xludf.DUMMYFUNCTION("""COMPUTED_VALUE"""),"Receipt number") -> Receipt number | D1: =IFERROR(__xludf.DUMMYFUNCTION("""COMPUTED_VALUE"""),"Receipt type") -> Receipt type | E1: =IFERROR(__xludf.DUMMYFUNCTION("""COMPUTED_VALUE"""),"Category") -> Category | F1: =IFERROR(__xludf.DUMMYFUNCTION("""COMPUTED_VALUE"""),"SKU") -> SKU | G1: =IFERROR(__xludf.DUMMYFUNCTION("""COMPUTED_VALUE"""),"Item") -> Item | H1: =IFERROR(__xludf.DUMMYFUNCTION("""COMPUTED_VALUE"""),"Variant") -> Variant | I1: =IFERROR(__xludf.DUMMYFUNCTION("""COMPUTED_VALUE"""),"Modifiers applied") -> Modifiers applied | J1: =IFERROR(__xludf.DUMMYFUNCTION("""COMPUTED_VALUE"""),"Quantity") -> Quantity | K1: =IFERROR(__xludf.DUMMYFUNCTION("""COMPUTED_VALUE"""),"Gross sales") -> Gross sales | L1: =IFERROR(__xludf.DUMMYFUNCTION("""COMPUTED_VALUE"""),"Discounts") -> Discounts | M1: =IFERROR(__xludf.DUMMYFUNCTION("""COMPUTED_VALUE"""),"Net sales") -> Net sales | N1: =IFERROR(__xludf.DUMMYFUNCTION("""COMPUTED_VALUE"""),"Cost of goods") -> Cost of goods | O1: =IFERROR(__xludf.DUMMYFUNCTION("""COMPUTED_VALUE"""),"Gross profit") -> Gross profit | P1: =IFERROR(__xludf.DUMMYFUNCTION("""COMPUTED_VALUE"""),"Taxes") -> Taxes | Q1: =IFERROR(__xludf.DUMMYFUNCTION("""COMPUTED_VALUE"""),"Dining option") -> Dining option | R1: =IFERROR(__xludf.DUMMYFUNCTION("""COMPUTED_VALUE"""),"POS") -> POS | S1: =IFERROR(__xludf.DUMMYFUNCTION("""COMPUTED_VALUE"""),"Store") -> Store | T1: =IFERROR(__xludf.DUMMYFUNCTION("""COMPUTED_VALUE"""),"Cashier name") -> Cashier name | U1: =IFERROR(__xludf.DUMMYFUNCTION("""COMPUTED_VALUE"""),"Customer name") -> Customer name | V1: =IFERROR(__xludf.DUMMYFUNCTION("""COMPUTED_VALUE"""),"Customer contacts") -> Customer contacts | W1: =IFERROR(__xludf.DUMMYFUNCTION("""COMPUTED_VALUE"""),"Comment") -> Comment | X1: =IFERROR(__xludf.DUMMYFUNCTION("""COMPUTED_VALUE"""),"Status") -> Status
A2: 29/09/2024 20:25,2-9570,Refund,Roti,10000,Roti Bawang Saus Keju,,,-1.000,-29524.00,0.00,-29524.00,-0.00,-29524.00,-1476.00,Take Away,Kedai,Temu Roti,Owner,,,,Closed | B2: =IFERROR(__xludf.DUMMYFUNCTION("SPLIT(A2,"","",0,0)"),45564.850694444445) -> 45564.851 | C2: =IFERROR(__xludf.DUMMYFUNCTION("""COMPUTED_VALUE"""),2801443.0) -> 2801443 | D2: =IFERROR(__xludf.DUMMYFUNCTION("""COMPUTED_VALUE"""),"Refund") -> Refund | E2: =IFERROR(__xludf.DUMMYFUNCTION("""COMPUTED_VALUE"""),"Roti") -> Roti | F2: =IFERROR(__xludf.DUMMYFUNCTION("""COMPUTED_VALUE"""),10000.0) -> 10000 | G2: =IFERROR(__xludf.DUMMYFUNCTION("""COMPUTED_VALUE"""),"Roti Bawang Saus Keju") -> Roti Bawang Saus Keju | J2: =IFERROR(__xludf.DUMMYFUNCTION("""COMPUTED_VALUE"""),-1.0) -> -1 | K2: =IFERROR(__xludf.DUMMYFUNCTION("""COMPUTED_VALUE"""),-29524.0) -> -29524 | L2: =IFERROR(__xludf.DUMMYFUNCTION("""COMPUTED_VALUE"""),0.0) -> 0 | M2: =IFERROR(__xludf.DUMMYFUNCTION("""COMPUTED_VALUE"""),-29524.0) -> -29524 | N2: =IFERROR(__xludf.DUMMYFUNCTION("""COMPUTED_VALUE"""),0.0) -> 0 | O2: =IFERROR(__xludf.DUMMYFUNCTION("""COMPUTED_VALUE"""),-29524.0) -> -29524 | P2: =IFERROR(__xludf.DUMMYFUNCTION("""COMPUTED_VALUE"""),-1476.0) -> -1476 | Q2: =IFERROR(__xludf.DUMMYFUNCTION("""COMPUTED_VALUE"""),"Take Away") -> Take Away | R2: =IFERROR(__xludf.DUMMYFUNCTION("""COMPUTED_VALUE"""),"Kedai") -> Kedai | S2: =IFERROR(__xludf.DUMMYFUNCTION("""COMPUTED_VALUE"""),"Temu Roti") -> Temu Roti | T2: =IFERROR(__xludf.DUMMYFUNCTION("""COMPUTED_VALUE"""),"Owner") -> Owner | X2: =IFERROR(__xludf.DUMMYFUNCTION("""COMPUTED_VALUE"""),"Closed") -> Closed
A3: 29/09/2024 20:24,2-9569,Refund,Minuman,10112,Air mineral,,,-2.000,-13334.00,0.00,-13334.00,-0.00,-13334.00,-667.00,Dine In,Kedai,Temu Roti,Owner,,,,Closed | B3: =IFERROR(__xludf.DUMMYFUNCTION("SPLIT(A3,"","",0,0)"),45564.85) -> 45564.85 | C3: =IFERROR(__xludf.DUMMYFUNCTION("""COMPUTED_VALUE"""),2801078.0) -> 2801078 | D3: =IFERROR(__xludf.DUMMYFUNCTION("""COMPUTED_VALUE"""),"Refund") -> Refund | E3: =IFERROR(__xludf.DUMMYFUNCTION("""COMPUTED_VALUE"""),"Minuman") -> Minuman | F3: =IFERROR(__xludf.DUMMYFUNCTION("""COMPUTED_VALUE"""),10112.0) -> 10112 | G3: =IFERROR(__xludf.DUMMYFUNCTION("""COMPUTED_VALUE"""),"Air mineral") -> Air mineral | J3: =IFERROR(__xludf.DUMMYFUNCTION("""COMPUTED_VALUE"""),-2.0) -> -2 | K3: =IFERROR(__xludf.DUMMYFUNCTION("""COMPUTED_VALUE"""),-13334.0) -> -13334 | L3: =IFERROR(__xludf.DUMMYFUNCTION("""COMPUTED_VALUE"""),0.0) -> 0 | M3: =IFERROR(__xludf.DUMMYFUNCTION("""COMPUTED_VALUE"""),-13334.0) -> -13334 | N3: =IFERROR(__xludf.DUMMYFUNCTION("""COMPUTED_VALUE"""),0.0) -> 0 | O3: =IFERROR(__xludf.DUMMYFUNCTION("""COMPUTED_VALUE"""),-13334.0) -> -13334 | P3: =IFERROR(__xludf.DUMMYFUNCTION("""COMPUTED_VALUE"""),-667.0) -> -667 | Q3: =IFERROR(__xludf.DUMMYFUNCTION("""COMPUTED_VALUE"""),"Dine In") -> Dine In | R3: =IFERROR(__xludf.DUMMYFUNCTION("""COMPUTED_VALUE"""),"Kedai") -> Kedai | S3: =IFERROR(__xludf.DUMMYFUNCTION("""COMPUTED_VALUE"""),"Temu Roti") -> Temu Roti | T3: =IFERROR(__xludf.DUMMYFUNCTION("""COMPUTED_VALUE"""),"Owner") -> Owner | X3: =IFERROR(__xludf.DUMMYFUNCTION("""COMPUTED_VALUE"""),"Closed") -> Closed
A4: 29/09/2024 20:16,2-9568,Sale,Roti,10002,Roti Cranberry,,,1.000,18571.00,0.00,18571.00,0.00,18571.00,929.00,Dine In,Kedai,Temu Roti,Owner,,,,Closed | B4: =IFERROR(__xludf.DUMMYFUNCTION("SPLIT(A4,"","",0,0)"),45564.84444444445) -> 45564.844 | C4: =IFERROR(__xludf.DUMMYFUNCTION("""COMPUTED_VALUE"""),2800712.0) -> 2800712 | D4: =IFERROR(__xludf.DUMMYFUNCTION("""COMPUTED_VALUE"""),"Sale") -> Sale | E4: =IFERROR(__xludf.DUMMYFUNCTION("""COMPUTED_VALUE"""),"Roti") -> Roti | F4: =IFERROR(__xludf.DUMMYFUNCTION("""COMPUTED_VALUE"""),10002.0) -> 10002 | G4: =IFERROR(__xludf.DUMMYFUNCTION("""COMPUTED_VALUE"""),"Roti Cranberry") -> Roti Cranberry | J4: =IFERROR(__xludf.DUMMYFUNCTION("""COMPUTED_VALUE"""),1.0) -> 1 | K4: =IFERROR(__xludf.DUMMYFUNCTION("""COMPUTED_VALUE"""),18571.0) -> 18571 | L4: =IFERROR(__xludf.DUMMYFUNCTION("""COMPUTED_VALUE"""),0.0) -> 0 | M4: =IFERROR(__xludf.DUMMYFUNCTION("""COMPUTED_VALUE"""),18571.0) -> 18571 | N4: =IFERROR(__xludf.DUMMYFUNCTION("""COMPUTED_VALUE"""),0.0) -> 0 | O4: =IFERROR(__xludf.DUMMYFUNCTION("""COMPUTED_VALUE"""),18571.0) -> 18571 | P4: =IFERROR(__xludf.DUMMYFUNCTION("""COMPUTED_VALUE"""),929.0) -> 929 | Q4: =IFERROR(__xludf.DUMMYFUNCTION("""COMPUTED_VALUE"""),"Dine In") -> Dine In | R4: =IFERROR(__xludf.DUMMYFUNCTION("""COMPUTED_VALUE"""),"Kedai") -> Kedai | S4: =IFERROR(__xludf.DUMMYFUNCTION("""COMPUTED_VALUE"""),"Temu Roti") -> Temu Roti | T4: =IFERROR(__xludf.DUMMYFUNCTION("""COMPUTED_VALUE"""),"Owner") -> Owner | X4: =IFERROR(__xludf.DUMMYFUNCTION("""COMPUTED_VALUE"""),"Closed") -> Closed
A5: 29/09/2024 18:40,2-9567,Sale,Minuman,10122,Rempah Madu Panas,,,2.000,43810.00,0.00,43810.00,0.00,43810.00,2191.00,Dine In,Kedai,Temu Roti,Owner,,,,Closed | B5: =IFERROR(__xludf.DUMMYFUNCTION("SPLIT(A5,"","",0,0)"),45564.77777777778) -> 45564.778 | C5: =IFERROR(__xludf.DUMMYFUNCTION("""COMPUTED_VALUE"""),2800347.0) -> 2800347 | D5: =IFERROR(__xludf.DUMMYFUNCTION("""COMPUTED_VALUE"""),"Sale") -> Sale | E5: =IFERROR(__xludf.DUMMYFUNCTION("""COMPUTED_VALUE"""),"Minuman") -> Minuman | F5: =IFERROR(__xludf.DUMMYFUNCTION("""COMPUTED_VALUE"""),10122.0) -> 10122 | G5: =IFERROR(__xludf.DUMMYFUNCTION("""COMPUTED_VALUE"""),"Rempah Madu Panas") -> Rempah Madu Panas | J5: =IFERROR(__xludf.DUMMYFUNCTION("""COMPUTED_VALUE"""),2.0) -> 2 | K5: =IFERROR(__xludf.DUMMYFUNCTION("""COMPUTED_VALUE"""),43810.0) -> 43810 | L5: =IFERROR(__xludf.DUMMYFUNCTION("""COMPUTED_VALUE"""),0.0) -> 0 | M5: =IFERROR(__xludf.DUMMYFUNCTION("""COMPUTED_VALUE"""),43810.0) -> 43810 | N5: =IFERROR(__xludf.DUMMYFUNCTION("""COMPUTED_VALUE"""),0.0) -> 0 | O5: =IFERROR(__xludf.DUMMYFUNCTION("""COMPUTED_VALUE"""),43810.0) -> 43810 | P5: =IFERROR(__xludf.DUMMYFUNCTION("""COMPUTED_VALUE"""),2191.0) -> 2191 | Q5: =IFERROR(__xludf.DUMMYFUNCTION("""COMPUTED_VALUE"""),"Dine In") -> Dine In | R5: =IFERROR(__xludf.DUMMYFUNCTION("""COMPUTED_VALUE"""),"Kedai") -> Kedai | S5: =IFERROR(__xludf.DUMMYFUNCTION("""COMPUTED_VALUE"""),"Temu Roti") -> Temu Roti | T5: =IFERROR(__xludf.DUMMYFUNCTION("""COMPUTED_VALUE"""),"Owner") -> Owner | X5: =IFERROR(__xludf.DUMMYFUNCTION("""COMPUTED_VALUE"""),"Closed") -> Closed
A6: 29/09/2024 18:40,2-9567,Sale,Kudapan,10051,Tahu baso,,,1.000,25238.00,0.00,25238.00,0.00,25238.00,1261.00,Dine In,Kedai,Temu Roti,Owner,,,,Closed | B6: =IFERROR(__xludf.DUMMYFUNCTION("SPLIT(A6,"","",0,0)"),45564.77777777778) -> 45564.778 | C6: =IFERROR(__xludf.DUMMYFUNCTION("""COMPUTED_VALUE"""),2800347.0) -> 2800347 | D6: =IFERROR(__xludf.DUMMYFUNCTION("""COMPUTED_VALUE"""),"Sale") -> Sale | E6: =IFERROR(__xludf.DUMMYFUNCTION("""COMPUTED_VALUE"""),"Kudapan") -> Kudapan | F6: =IFERROR(__xludf.DUMMYFUNCTION("""COMPUTED_VALUE"""),10051.0) -> 10051 | G6: =IFERROR(__xludf.DUMMYFUNCTION("""COMPUTED_VALUE"""),"Tahu baso") -> Tahu baso | J6: =IFERROR(__xludf.DUMMYFUNCTION("""COMPUTED_VALUE"""),1.0) -> 1 | K6: =IFERROR(__xludf.DUMMYFUNCTION("""COMPUTED_VALUE"""),25238.0) -> 25238 | L6: =IFERROR(__xludf.DUMMYFUNCTION("""COMPUTED_VALUE"""),0.0) -> 0 | M6: =IFERROR(__xludf.DUMMYFUNCTION("""COMPUTED_VALUE"""),25238.0) -> 25238 | N6: =IFERROR(__xludf.DUMMYFUNCTION("""COMPUTED_VALUE"""),0.0) -> 0 | O6: =IFERROR(__xludf.DUMMYFUNCTION("""COMPUTED_VALUE"""),25238.0) -> 25238 | P6: =IFERROR(__xludf.DUMMYFUNCTION("""COMPUTED_VALUE"""),1261.0) -> 1261 | Q6: =IFERROR(__xludf.DUMMYFUNCTION("""COMPUTED_VALUE"""),"Dine In") -> Dine In | R6: =IFERROR(__xludf.DUMMYFUNCTION("""COMPUTED_VALUE"""),"Kedai") -> Kedai | S6: =IFERROR(__xludf.DUMMYFUNCTION("""COMPUTED_VALUE"""),"Temu Roti") -> Temu Roti | T6: =IFERROR(__xludf.DUMMYFUNCTION("""COMPUTED_VALUE"""),"Owner") -> Owner | X6: =IFERROR(__xludf.DUMMYFUNCTION("""COMPUTED_VALUE"""),"Closed") -> Closed
A7: 29/09/2024 18:40,2-9566,Refund,Minuman,10122,Rempah Madu Panas,,,-1.000,-21905.00,0.00,-21905.00,-0.00,-21905.00,-1095.00,Dine In,Kedai,Temu Roti,Owner,,,,Closed | B7: =IFERROR(__xludf.DUMMYFUNCTION("SPLIT(A7,"","",0,0)"),45564.77777777778) -> 45564.778 | C7: =IFERROR(__xludf.DUMMYFUNCTION("""COMPUTED_VALUE"""),2799982.0) -> 2799982 | D7: =IFERROR(__xludf.DUMMYFUNCTION("""COMPUTED_VALUE"""),"Refund") -> Refund | E7: =IFERROR(__xludf.DUMMYFUNCTION("""COMPUTED_VALUE"""),"Minuman") -> Minuman | F7: =IFERROR(__xludf.DUMMYFUNCTION("""COMPUTED_VALUE"""),10122.0) -> 10122 | G7: =IFERROR(__xludf.DUMMYFUNCTION("""COMPUTED_VALUE"""),"Rempah Madu Panas") -> Rempah Madu Panas | J7: =IFERROR(__xludf.DUMMYFUNCTION("""COMPUTED_VALUE"""),-1.0) -> -1 | K7: =IFERROR(__xludf.DUMMYFUNCTION("""COMPUTED_VALUE"""),-21905.0) -> -21905 | L7: =IFERROR(__xludf.DUMMYFUNCTION("""COMPUTED_VALUE"""),0.0) -> 0 | M7: =IFERROR(__xludf.DUMMYFUNCTION("""COMPUTED_VALUE"""),-21905.0) -> -21905 | N7: =IFERROR(__xludf.DUMMYFUNCTION("""COMPUTED_VALUE"""),0.0) -> 0 | O7: =IFERROR(__xludf.DUMMYFUNCTION("""COMPUTED_VALUE"""),-21905.0) -> -21905 | P7: =IFERROR(__xludf.DUMMYFUNCTION("""COMPUTED_VALUE"""),-1095.0) -> -1095 | Q7: =IFERROR(__xludf.DUMMYFUNCTION("""COMPUTED_VALUE"""),"Dine In") -> Dine In | R7: =IFERROR(__xludf.DUMMYFUNCTION("""COMPUTED_VALUE"""),"Kedai") -> Kedai | S7: =IFERROR(__xludf.DUMMYFUNCTION("""COMPUTED_VALUE"""),"Temu Roti") -> Temu Roti | T7: =IFERROR(__xludf.DUMMYFUNCTION("""COMPUTED_VALUE"""),"Owner") -> Owner | X7: =IFERROR(__xludf.DUMMYFUNCTION("""COMPUTED_VALUE"""),"Closed") -> Closed
A8: 29/09/2024 18:40,2-9566,Refund,Kudapan,10051,Tahu baso,,,-2.000,-50476.00,0.00,-50476.00,-0.00,-50476.00,-2524.00,Dine In,Kedai,Temu Roti,Owner,,,,Closed | B8: =IFERROR(__xludf.DUMMYFUNCTION("SPLIT(A8,"","",0,0)"),45564.77777777778) -> 45564.778 | C8: =IFERROR(__xludf.DUMMYFUNCTION("""COMPUTED_VALUE"""),2799982.0) -> 2799982 | D8: =IFERROR(__xludf.DUMMYFUNCTION("""COMPUTED_VALUE"""),"Refund") -> Refund | E8: =IFERROR(__xludf.DUMMYFUNCTION("""COMPUTED_VALUE"""),"Kudapan") -> Kudapan | F8: =IFERROR(__xludf.DUMMYFUNCTION("""COMPUTED_VALUE"""),10051.0) -> 10051 | G8: =IFERROR(__xludf.DUMMYFUNCTION("""COMPUTED_VALUE"""),"Tahu baso") -> Tahu baso | J8: =IFERROR(__xludf.DUMMYFUNCTION("""COMPUTED_VALUE"""),-2.0) -> -2 | K8: =IFERROR(__xludf.DUMMYFUNCTION("""COMPUTED_VALUE"""),-50476.0) -> -50476 | L8: =IFERROR(__xludf.DUMMYFUNCTION("""COMPUTED_VALUE"""),0.0) -> 0 | M8: =IFERROR(__xludf.DUMMYFUNCTION("""COMPUTED_VALUE"""),-50476.0) -> -50476 | N8: =IFERROR(__xludf.DUMMYFUNCTION("""COMPUTED_VALUE"""),0.0) -> 0 | O8: =IFERROR(__xludf.DUMMYFUNCTION("""COMPUTED_VALUE"""),-50476.0) -> -50476 | P8: =IFERROR(__xludf.DUMMYFUNCTION("""COMPUTED_VALUE"""),-2524.0) -> -2524 | Q8: =IFERROR(__xludf.DUMMYFUNCTION("""COMPUTED_VALUE"""),"Dine In") -> Dine In | R8: =IFERROR(__xludf.DUMMYFUNCTION("""COMPUTED_VALUE"""),"Kedai") -> Kedai | S8: =IFERROR(__xludf.DUMMYFUNCTION("""COMPUTED_VALUE"""),"Temu Roti") -> Temu Roti | T8: =IFERROR(__xludf.DUMMYFUNCTION("""COMPUTED_VALUE"""),"Owner") -> Owner | X8: =IFERROR(__xludf.DUMMYFUNCTION("""COMPUTED_VALUE"""),"Closed") -> Closed
A9: 29/09/2024 18:40,2-9566,Refund,Minuman,10122,Rempah Madu Panas,,,-1.000,-21905.00,0.00,-21905.00,-0.00,-21905.00,-1095.00,Dine In,Kedai,Temu Roti,Owner,,,,Closed | B9: =IFERROR(__xludf.DUMMYFUNCTION("SPLIT(A9,"","",0,0)"),45564.77777777778) -> 45564.778 | C9: =IFERROR(__xludf.DUMMYFUNCTION("""COMPUTED_VALUE"""),2799982.0) -> 2799982 | D9: =IFERROR(__xludf.DUMMYFUNCTION("""COMPUTED_VALUE"""),"Refund") -> Refund | E9: =IFERROR(__xludf.DUMMYFUNCTION("""COMPUTED_VALUE"""),"Minuman") -> Minuman | F9: =IFERROR(__xludf.DUMMYFUNCTION("""COMPUTED_VALUE"""),10122.0) -> 10122 | G9: =IFERROR(__xludf.DUMMYFUNCTION("""COMPUTED_VALUE"""),"Rempah Madu Panas") -> Rempah Madu Panas | J9: =IFERROR(__xludf.DUMMYFUNCTION("""COMPUTED_VALUE"""),-1.0) -> -1 | K9: =IFERROR(__xludf.DUMMYFUNCTION("""COMPUTED_VALUE"""),-21905.0) -> -21905 | L9: =IFERROR(__xludf.DUMMYFUNCTION("""COMPUTED_VALUE"""),0.0) -> 0 | M9: =IFERROR(__xludf.DUMMYFUNCTION("""COMPUTED_VALUE"""),-21905.0) -> -21905 | N9: =IFERROR(__xludf.DUMMYFUNCTION("""COMPUTED_VALUE"""),0.0) -> 0 | O9: =IFERROR(__xludf.DUMMYFUNCTION("""COMPUTED_VALUE"""),-21905.0) -> -21905 | P9: =IFERROR(__xludf.DUMMYFUNCTION("""COMPUTED_VALUE"""),-1095.0) -> -1095 | Q9: =IFERROR(__xludf.DUMMYFUNCTION("""COMPUTED_VALUE"""),"Dine In") -> Dine In | R9: =IFERROR(__xludf.DUMMYFUNCTION("""COMPUTED_VALUE"""),"Kedai") -> Kedai | S9: =IFERROR(__xludf.DUMMYFUNCTION("""COMPUTED_VALUE"""),"Temu Roti") -> Temu Roti | T9: =IFERROR(__xludf.DUMMYFUNCTION("""COMPUTED_VALUE"""),"Owner") -> Owner | X9: =IFERROR(__xludf.DUMMYFUNCTION("""COMPUTED_VALUE"""),"Closed") -> Closed
A10: 29/09/2024 18:36,2-9565,Sale,Minuman,10122,Rempah Madu Panas,,,1.000,21905.00,0.00,21905.00,0.00,21905.00,1095.00,Dine In,Kedai,Temu Roti,Owner,,,,Closed | B10: =IFERROR(__xludf.DUMMYFUNCTION("SPLIT(A10,"","",0,0)"),45564.775) -> 45564.775 | C10: =IFERROR(__xludf.DUMMYFUNCTION("""COMPUTED_VALUE"""),2799617.0) -> 2799617 | D10: =IFERROR(__xludf.DUMMYFUNCTION("""COMPUTED_VALUE"""),"Sale") -> Sale | E10: =IFERROR(__xludf.DUMMYFUNCTION("""COMPUTED_VALUE"""),"Minuman") -> Minuman | F10: =IFERROR(__xludf.DUMMYFUNCTION("""COMPUTED_VALUE"""),10122.0) -> 10122 | G10: =IFERROR(__xludf.DUMMYFUNCTION("""COMPUTED_VALUE"""),"Rempah Madu Panas") -> Rempah Madu Panas | J10: =IFERROR(__xludf.DUMMYFUNCTION("""COMPUTED_VALUE"""),1.0) -> 1 | K10: =IFERROR(__xludf.DUMMYFUNCTION("""COMPUTED_VALUE"""),21905.0) -> 21905 | L10: =IFERROR(__xludf.DUMMYFUNCTION("""COMPUTED_VALUE"""),0.0) -> 0 | M10: =IFERROR(__xludf.DUMMYFUNCTION("""COMPUTED_VALUE"""),21905.0) -> 21905 | N10: =IFERROR(__xludf.DUMMYFUNCTION("""COMPUTED_VALUE"""),0.0) -> 0 | O10: =IFERROR(__xludf.DUMMYFUNCTION("""COMPUTED_VALUE"""),21905.0) -> 21905 | P10: =IFERROR(__xludf.DUMMYFUNCTION("""COMPUTED_VALUE"""),1095.0) -> 1095 | Q10: =IFERROR(__xludf.DUMMYFUNCTION("""COMPUTED_VALUE"""),"Dine In") -> Dine In | R10: =IFERROR(__xludf.DUMMYFUNCTION("""COMPUTED_VALUE"""),"Kedai") -> Kedai | S10: =IFERROR(__xludf.DUMMYFUNCTION("""COMPUTED_VALUE"""),"Temu Roti") -> Temu Roti | T10: =IFERROR(__xludf.DUMMYFUNCTION("""COMPUTED_VALUE"""),"Owner") -> Owner | X10: =IFERROR(__xludf.DUMMYFUNCTION("""COMPUTED_VALUE"""),"Closed") -> Closed
A11: 29/09/2024 18:36,2-9565,Sale,Kudapan,10051,Tahu baso,,,2.000,50476.00,0.00,50476.00,0.00,50476.00,2524.00,Dine In,Kedai,Temu Roti,Owner,,,,Closed | B11: =IFERROR(__xludf.DUMMYFUNCTION("SPLIT(A11,"","",0,0)"),45564.775) -> 45564.775 | C11: =IFERROR(__xludf.DUMMYFUNCTION("""COMPUTED_VALUE"""),2799617.0) -> 2799617 | D11: =IFERROR(__xludf.DUMMYFUNCTION("""COMPUTED_VALUE"""),"Sale") -> Sale | E11: =IFERROR(__xludf.DUMMYFUNCTION("""COMPUTED_VALUE"""),"Kudapan") -> Kudapan | F11: =IFERROR(__xludf.DUMMYFUNCTION("""COMPUTED_VALUE"""),10051.0) -> 10051 | G11: =IFERROR(__xludf.DUMMYFUNCTION("""COMPUTED_VALUE"""),"Tahu baso") -> Tahu baso | J11: =IFERROR(__xludf.DUMMYFUNCTION("""COMPUTED_VALUE"""),2.0) -> 2 | K11: =IFERROR(__xludf.DUMMYFUNCTION("""COMPUTED_VALUE"""),50476.0) -> 50476 | L11: =IFERROR(__xludf.DUMMYFUNCTION("""COMPUTED_VALUE"""),0.0) -> 0 | M11: =IFERROR(__xludf.DUMMYFUNCTION("""COMPUTED_VALUE"""),50476.0) -> 50476 | N11: =IFERROR(__xludf.DUMMYFUNCTION("""COMPUTED_VALUE"""),0.0) -> 0 | O11: =IFERROR(__xludf.DUMMYFUNCTION("""COMPUTED_VALUE"""),50476.0) -> 50476 | P11: =IFERROR(__xludf.DUMMYFUNCTION("""COMPUTED_VALUE"""),2524.0) -> 2524 | Q11: =IFERROR(__xludf.DUMMYFUNCTION("""COMPUTED_VALUE"""),"Dine In") -> Dine In | R11: =IFERROR(__xludf.DUMMYFUNCTION("""COMPUTED_VALUE"""),"Kedai") -> Kedai | S11: =IFERROR(__xludf.DUMMYFUNCTION("""COMPUTED_VALUE"""),"Temu Roti") -> Temu Roti | T11: =IFERROR(__xludf.DUMMYFUNCTION("""COMPUTED_VALUE"""),"Owner") -> Owner | X11: =IFERROR(__xludf.DUMMYFUNCTION("""COMPUTED_VALUE"""),"Closed") -> Closed
A12: 29/09/2024 18:36,2-9565,Sale,Minuman,10122,Rempah Madu Panas,,,1.000,21905.00,0.00,21905.00,0.00,21905.00,1095.00,Dine In,Kedai,Temu Roti,Owner,,,,Closed | B12: =IFERROR(__xludf.DUMMYFUNCTION("SPLIT(A12,"","",0,0)"),45564.775) -> 45564.775 | C12: =IFERROR(__xludf.DUMMYFUNCTION("""COMPUTED_VALUE"""),2799617.0) -> 2799617 | D12: =IFERROR(__xludf.DUMMYFUNCTION("""COMPUTED_VALUE"""),"Sale") -> Sale | E12: =IFERROR(__xludf.DUMMYFUNCTION("""COMPUTED_VALUE"""),"Minuman") -> Minuman | F12: =IFERROR(__xludf.DUMMYFUNCTION("""COMPUTED_VALUE"""),10122.0) -> 10122 | G12: =IFERROR(__xludf.DUMMYFUNCTION("""COMPUTED_VALUE"""),"Rempah Madu Panas") -> Rempah Madu Panas | J12: =IFERROR(__xludf.DUMMYFUNCTION("""COMPUTED_VALUE"""),1.0) -> 1 | K12: =IFERROR(__xludf.DUMMYFUNCTION("""COMPUTED_VALUE"""),21905.0) -> 21905 | L12: =IFERROR(__xludf.DUMMYFUNCTION("""COMPUTED_VALUE"""),0.0) -> 0 | M12: =IFERROR(__xludf.DUMMYFUNCTION("""COMPUTED_VALUE"""),21905.0) -> 21905 | N12: =IFERROR(__xludf.DUMMYFUNCTION("""COMPUTED_VALUE"""),0.0) -> 0 | O12: =IFERROR(__xludf.DUMMYFUNCTION("""COMPUTED_VALUE"""),21905.0) -> 21905 | P12: =IFERROR(__xludf.DUMMYFUNCTION("""COMPUTED_VALUE"""),1095.0) -> 1095 | Q12: =IFERROR(__xludf.DUMMYFUNCTION("""COMPUTED_VALUE"""),"Dine In") -> Dine In | R12: =IFERROR(__xludf.DUMMYFUNCTION("""COMPUTED_VALUE"""),"Kedai") -> Kedai | S12: =IFERROR(__xludf.DUMMYFUNCTION("""COMPUTED_VALUE"""),"Temu Roti") -> Temu Roti | T12: =IFERROR(__xludf.DUMMYFUNCTION("""COMPUTED_VALUE"""),"Owner") -> Owner | X12: =IFERROR(__xludf.DUMMYFUNCTION("""COMPUTED_VALUE"""),"Closed") -> Closed
A13: 29/09/2024 18:32,2-9564,Sale,Hidangan Utama,10104,Chicken Claypot Rice,,,1.000,34762.00,0.00,34762.00,0.00,34762.00,1738.00,Dine In,Kedai,Temu Roti,Owner,,,,Closed | B13: =IFERROR(__xludf.DUMMYFUNCTION("SPLIT(A13,"","",0,0)"),45564.77222222222) -> 45564.772 | C13: =IFERROR(__xludf.DUMMYFUNCTION("""COMPUTED_VALUE"""),2799251.0) -> 2799251 | D13: =IFERROR(__xludf.DUMMYFUNCTION("""COMPUTED_VALUE"""),"Sale") -> Sale | E13: =IFERROR(__xludf.DUMMYFUNCTION("""COMPUTED_VALUE"""),"Hidangan Utama") -> Hidangan Utama | F13: =IFERROR(__xludf.DUMMYFUNCTION("""COMPUTED_VALUE"""),10104.0) -> 10104 | G13: =IFERROR(__xludf.DUMMYFUNCTION("""COMPUTED_VALUE"""),"Chicken Claypot Rice") -> Chicken Claypot Rice | J13: =IFERROR(__xludf.DUMMYFUNCTION("""COMPUTED_VALUE"""),1.0) -> 1 | K13: =IFERROR(__xludf.DUMMYFUNCTION("""COMPUTED_VALUE"""),34762.0) -> 34762 | L13: =IFERROR(__xludf.DUMMYFUNCTION("""COMPUTED_VALUE"""),0.0) -> 0 | M13: =IFERROR(__xludf.DUMMYFUNCTION("""COMPUTED_VALUE"""),34762.0) -> 34762 | N13: =IFERROR(__xludf.DUMMYFUNCTION("""COMPUTED_VALUE"""),0.0) -> 0 | O13: =IFERROR(__xludf.DUMMYFUNCTION("""COMPUTED_VALUE"""),34762.0) -> 34762 | P13: =IFERROR(__xludf.DUMMYFUNCTION("""COMPUTED_VALUE"""),1738.0) -> 1738 | Q13: =IFERROR(__xludf.DUMMYFUNCTION("""COMPUTED_VALUE"""),"Dine In") -> Dine In | R13: =IFERROR(__xludf.DUMMYFUNCTION("""COMPUTED_VALUE"""),"Kedai") -> Kedai | S13: =IFERROR(__xludf.DUMMYFUNCTION("""COMPUTED_VALUE"""),"Temu Roti") -> Temu Roti | T13: =IFERROR(__xludf.DUMMYFUNCTION("""COMPUTED_VALUE"""),"Owner") -> Owner | X13: =IFERROR(__xludf.DUMMYFUNCTION("""COMPUTED_VALUE"""),"Closed") -> Closed
A14: 29/09/2024 18:32,2-9564,Sale,Minuman,10119,Teh Tawar Dingin,,,1.000,7143.00,0.00,7143.00,0.00,7143.00,357.00,Dine In,Kedai,Temu Roti,Owner,,,,Closed | B14: =IFERROR(__xludf.DUMMYFUNCTION("SPLIT(A14,"","",0,0)"),45564.77222222222) -> 45564.772 | C14: =IFERROR(__xludf.DUMMYFUNCTION("""COMPUTED_VALUE"""),2799251.0) -> 2799251 | D14: =IFERROR(__xludf.DUMMYFUNCTION("""COMPUTED_VALUE"""),"Sale") -> Sale | E14: =IFERROR(__xludf.DUMMYFUNCTION("""COMPUTED_VALUE"""),"Minuman") -> Minuman | F14: =IFERROR(__xludf.DUMMYFUNCTION("""COMPUTED_VALUE"""),10119.0) -> 10119 | G14: =IFERROR(__xludf.DUMMYFUNCTION("""COMPUTED_VALUE"""),"Teh Tawar Dingin") -> Teh Tawar Dingin | J14: =IFERROR(__xludf.DUMMYFUNCTION("""COMPUTED_VALUE"""),1.0) -> 1 | K14: =IFERROR(__xludf.DUMMYFUNCTION("""COMPUTED_VALUE"""),7143.0) -> 7143 | L14: =IFERROR(__xludf.DUMMYFUNCTION("""COMPUTED_VALUE"""),0.0) -> 0 | M14: =IFERROR(__xludf.DUMMYFUNCTION("""COMPUTED_VALUE"""),7143.0) -> 7143 | N14: =IFERROR(__xludf.DUMMYFUNCTION("""COMPUTED_VALUE"""),0.0) -> 0 | O14: =IFERROR(__xludf.DUMMYFUNCTION("""COMPUTED_VALUE"""),7143.0) -> 7143 | P14: =IFERROR(__xludf.DUMMYFUNCTION("""COMPUTED_VALUE"""),357.0) -> 357 | Q14: =IFERROR(__xludf.DUMMYFUNCTION("""COMPUTED_VALUE"""),"Dine In") -> Dine In | R14: =IFERROR(__xludf.DUMMYFUNCTION("""COMPUTED_VALUE"""),"Kedai") -> Kedai | S14: =IFERROR(__xludf.DUMMYFUNCTION("""COMPUTED_VALUE"""),"Temu Roti") -> Temu Roti | T14: =IFERROR(__xludf.DUMMYFUNCTION("""COMPUTED_VALUE"""),"Owner") -> Owner | X14: =IFERROR(__xludf.DUMMYFUNCTION("""COMPUTED_VALUE"""),"Closed") -> Closed
A15: 29/09/2024 18:16,2-9563,Sale,Minuman,10026,Es Kopi Lemon,,,1.000,21905.00,0.00,21905.00,0.00,21905.00,1095.00,Dine In,Kedai,Temu Roti,Owner,,,,Closed | B15: =IFERROR(__xludf.DUMMYFUNCTION("SPLIT(A15,"","",0,0)"),45564.76111111111) -> 45564.761 | C15: =IFERROR(__xludf.DUMMYFUNCTION("""COMPUTED_VALUE"""),2798886.0) -> 2798886 | D15: =IFERROR(__xludf.DUMMYFUNCTION("""COMPUTED_VALUE"""),"Sale") -> Sale | E15: =IFERROR(__xludf.DUMMYFUNCTION("""COMPUTED_VALUE"""),"Minuman") -> Minuman | F15: =IFERROR(__xludf.DUMMYFUNCTION("""COMPUTED_VALUE"""),10026.0) -> 10026 | G15: =IFERROR(__xludf.DUMMYFUNCTION("""COMPUTED_VALUE"""),"Es Kopi Lemon") -> Es Kopi Lemon | J15: =IFERROR(__xludf.DUMMYFUNCTION("""COMPUTED_VALUE"""),1.0) -> 1 | K15: =IFERROR(__xludf.DUMMYFUNCTION("""COMPUTED_VALUE"""),21905.0) -> 21905 | L15: =IFERROR(__xludf.DUMMYFUNCTION("""COMPUTED_VALUE"""),0.0) -> 0 | M15: =IFERROR(__xludf.DUMMYFUNCTION("""COMPUTED_VALUE"""),21905.0) -> 21905 | N15: =IFERROR(__xludf.DUMMYFUNCTION("""COMPUTED_VALUE"""),0.0) -> 0 | O15: =IFERROR(__xludf.DUMMYFUNCTION("""COMPUTED_VALUE"""),21905.0) -> 21905 | P15: =IFERROR(__xludf.DUMMYFUNCTION("""COMPUTED_VALUE"""),1095.0) -> 1095 | Q15: =IFERROR(__xludf.DUMMYFUNCTION("""COMPUTED_VALUE"""),"Dine In") -> Dine In | R15: =IFERROR(__xludf.DUMMYFUNCTION("""COMPUTED_VALUE"""),"Kedai") -> Kedai | S15: =IFERROR(__xludf.DUMMYFUNCTION("""COMPUTED_VALUE"""),"Temu Roti") -> Temu Roti | T15: =IFERROR(__xludf.DUMMYFUNCTION("""COMPUTED_VALUE"""),"Owner") -> Owner | X15: =IFERROR(__xludf.DUMMYFUNCTION("""COMPUTED_VALUE"""),"Closed") -> Closed
A16: 29/09/2024 18:16,2-9563,Sale,Minuman,10107,Korean Mango Fresh Milk,,,1.000,26667.00,0.00,26667.00,0.00,26667.00,1334.00,Dine In,Kedai,Temu Roti,Owner,,,,Closed | B16: =IFERROR(__xludf.DUMMYFUNCTION("SPLIT(A16,"","",0,0)"),45564.76111111111) -> 45564.761 | C16: =IFERROR(__xludf.DUMMYFUNCTION("""COMPUTED_VALUE"""),2798886.0) -> 2798886 | D16: =IFERROR(__xludf.DUMMYFUNCTION("""COMPUTED_VALUE"""),"Sale") -> Sale | E16: =IFERROR(__xludf.DUMMYFUNCTION("""COMPUTED_VALUE"""),"Minuman") -> Minuman | F16: =IFERROR(__xludf.DUMMYFUNCTION("""COMPUTED_VALUE"""),10107.0) -> 10107 | G16: =IFERROR(__xludf.DUMMYFUNCTION("""COMPUTED_VALUE"""),"Korean Mango Fresh Milk") -> Korean Mango Fresh Milk | J16: =IFERROR(__xludf.DUMMYFUNCTION("""COMPUTED_VALUE"""),1.0) -> 1 | K16: =IFERROR(__xludf.DUMMYFUNCTION("""COMPUTED_VALUE"""),26667.0) -> 26667 | L16: =IFERROR(__xludf.DUMMYFUNCTION("""COMPUTED_VALUE"""),0.0) -> 0 | M16: =IFERROR(__xludf.DUMMYFUNCTION("""COMPUTED_VALUE"""),26667.0) -> 26667 | N16: =IFERROR(__xludf.DUMMYFUNCTION("""COMPUTED_VALUE"""),0.0) -> 0 | O16: =IFERROR(__xludf.DUMMYFUNCTION("""COMPUTED_VALUE"""),26667.0) -> 26667 | P16: =IFERROR(__xludf.DUMMYFUNCTION("""COMPUTED_VALUE"""),1334.0) -> 1334 | Q16: =IFERROR(__xludf.DUMMYFUNCTION("""COMPUTED_VALUE"""),"Dine In") -> Dine In | R16: =IFERROR(__xludf.DUMMYFUNCTION("""COMPUTED_VALUE"""),"Kedai") -> Kedai | S16: =IFERROR(__xludf.DUMMYFUNCTION("""COMPUTED_VALUE"""),"Temu Roti") -> Temu Roti | T16: =IFERROR(__xludf.DUMMYFUNCTION("""COMPUTED_VALUE"""),"Owner") -> Owner | X16: =IFERROR(__xludf.DUMMYFUNCTION("""COMPUTED_VALUE"""),"Closed") -> Closed
A17: 29/09/2024 18:12,2-9562,Sale,Minuman,10056,Susu murni moca,,,1.000,19524.00,0.00,19524.00,0.00,19524.00,976.00,Dine In,Kedai,Temu Roti,Owner,,,,Closed | B17: =IFERROR(__xludf.DUMMYFUNCTION("SPLIT(A17,"","",0,0)"),45564.75833333333) -> 45564.758 | C17: =IFERROR(__xludf.DUMMYFUNCTION("""COMPUTED_VALUE"""),2798521.0) -> 2798521 | D17: =IFERROR(__xludf.DUMMYFUNCTION("""COMPUTED_VALUE"""),"Sale") -> Sale | E17: =IFERROR(__xludf.DUMMYFUNCTION("""COMPUTED_VALUE"""),"Minuman") -> Minuman | F17: =IFERROR(__xludf.DUMMYFUNCTION("""COMPUTED_VALUE"""),10056.0) -> 10056 | G17: =IFERROR(__xludf.DUMMYFUNCTION("""COMPUTED_VALUE"""),"Susu murni moca") -> Susu murni moca | J17: =IFERROR(__xludf.DUMMYFUNCTION("""COMPUTED_VALUE"""),1.0) -> 1 | K17: =IFERROR(__xludf.DUMMYFUNCTION("""COMPUTED_VALUE"""),19524.0) -> 19524 | L17: =IFERROR(__xludf.DUMMYFUNCTION("""COMPUTED_VALUE"""),0.0) -> 0 | M17: =IFERROR(__xludf.DUMMYFUNCTION("""COMPUTED_VALUE"""),19524.0) -> 19524 | N17: =IFERROR(__xludf.DUMMYFUNCTION("""COMPUTED_VALUE"""),0.0) -> 0 | O17: =IFERROR(__xludf.DUMMYFUNCTION("""COMPUTED_VALUE"""),19524.0) -> 19524 | P17: =IFERROR(__xludf.DUMMYFUNCTION("""COMPUTED_VALUE"""),976.0) -> 976 | Q17: =IFERROR(__xludf.DUMMYFUNCTION("""COMPUTED_VALUE"""),"Dine In") -> Dine In | R17: =IFERROR(__xludf.DUMMYFUNCTION("""COMPUTED_VALUE"""),"Kedai") -> Kedai | S17: =IFERROR(__xludf.DUMMYFUNCTION("""COMPUTED_VALUE"""),"Temu Roti") -> Temu Roti | T17: =IFERROR(__xludf.DUMMYFUNCTION("""COMPUTED_VALUE"""),"Owner") -> Owner | X17: =IFERROR(__xludf.DUMMYFUNCTION("""COMPUTED_VALUE"""),"Closed") -> Closed
A18: 29/09/2024 17:59,2-9561,Sale,Kudapan,10009,Jamur Enoki Krispi,,,1.000,26667.00,0.00,26667.00,0.00,26667.00,1333.00,Dine In,Kedai,Temu Roti,Owner,,,,Closed | B18: =IFERROR(__xludf.DUMMYFUNCTION("SPLIT(A18,"","",0,0)"),45564.74930555555) -> 45564.749 | C18: =IFERROR(__xludf.DUMMYFUNCTION("""COMPUTED_VALUE"""),2798156.0) -> 2798156 | D18: =IFERROR(__xludf.DUMMYFUNCTION("""COMPUTED_VALUE"""),"Sale") -> Sale | E18: =IFERROR(__xludf.DUMMYFUNCTION("""COMPUTED_VALUE"""),"Kudapan") -> Kudapan | F18: =IFERROR(__xludf.DUMMYFUNCTION("""COMPUTED_VALUE"""),10009.0) -> 10009 | G18: =IFERROR(__xludf.DUMMYFUNCTION("""COMPUTED_VALUE"""),"Jamur Enoki Krispi") -> Jamur Enoki Krispi | J18: =IFERROR(__xludf.DUMMYFUNCTION("""COMPUTED_VALUE"""),1.0) -> 1 | K18: =IFERROR(__xludf.DUMMYFUNCTION("""COMPUTED_VALUE"""),26667.0) -> 26667 | L18: =IFERROR(__xludf.DUMMYFUNCTION("""COMPUTED_VALUE"""),0.0) -> 0 | M18: =IFERROR(__xludf.DUMMYFUNCTION("""COMPUTED_VALUE"""),26667.0) -> 26667 | N18: =IFERROR(__xludf.DUMMYFUNCTION("""COMPUTED_VALUE"""),0.0) -> 0 | O18: =IFERROR(__xludf.DUMMYFUNCTION("""COMPUTED_VALUE"""),26667.0) -> 26667 | P18: =IFERROR(__xludf.DUMMYFUNCTION("""COMPUTED_VALUE"""),1333.0) -> 1333 | Q18: =IFERROR(__xludf.DUMMYFUNCTION("""COMPUTED_VALUE"""),"Dine In") -> Dine In | R18: =IFERROR(__xludf.DUMMYFUNCTION("""COMPUTED_VALUE"""),"Kedai") -> Kedai | S18: =IFERROR(__xludf.DUMMYFUNCTION("""COMPUTED_VALUE"""),"Temu Roti") -> Temu Roti | T18: =IFERROR(__xludf.DUMMYFUNCTION("""COMPUTED_VALUE"""),"Owner") -> Owner | X18: =IFERROR(__xludf.DUMMYFUNCTION("""COMPUTED_VALUE"""),"Closed") -> Closed
A19: 29/09/2024 17:53,2-9560,Sale,Hidangan Utama,10104,Chicken Claypot Rice,,,1.000,34762.00,0.00,34762.00,0.00,34762.00,1738.00,Dine In,Kedai,Temu Roti,Owner,,,,Closed | B19: =IFERROR(__xludf.DUMMYFUNCTION("SPLIT(A19,"","",0,0)"),45564.74513888889) -> 45564.745 | C19: =IFERROR(__xludf.DUMMYFUNCTION("""COMPUTED_VALUE"""),2797790.0) -> 2797790 | D19: =IFERROR(__xludf.DUMMYFUNCTION("""COMPUTED_VALUE"""),"Sale") -> Sale | E19: =IFERROR(__xludf.DUMMYFUNCTION("""COMPUTED_VALUE"""),"Hidangan Utama") -> Hidangan Utama | F19: =IFERROR(__xludf.DUMMYFUNCTION("""COMPUTED_VALUE"""),10104.0) -> 10104 | G19: =IFERROR(__xludf.DUMMYFUNCTION("""COMPUTED_VALUE"""),"Chicken Claypot Rice") -> Chicken Claypot Rice | J19: =IFERROR(__xludf.DUMMYFUNCTION("""COMPUTED_VALUE"""),1.0) -> 1 | K19: =IFERROR(__xludf.DUMMYFUNCTION("""COMPUTED_VALUE"""),34762.0) -> 34762 | L19: =IFERROR(__xludf.DUMMYFUNCTION("""COMPUTED_VALUE"""),0.0) -> 0 | M19: =IFERROR(__xludf.DUMMYFUNCTION("""COMPUTED_VALUE"""),34762.0) -> 34762 | N19: =IFERROR(__xludf.DUMMYFUNCTION("""COMPUTED_VALUE"""),0.0) -> 0 | O19: =IFERROR(__xludf.DUMMYFUNCTION("""COMPUTED_VALUE"""),34762.0) -> 34762 | P19: =IFERROR(__xludf.DUMMYFUNCTION("""COMPUTED_VALUE"""),1738.0) -> 1738 | Q19: =IFERROR(__xludf.DUMMYFUNCTION("""COMPUTED_VALUE"""),"Dine In") -> Dine In | R19: =IFERROR(__xludf.DUMMYFUNCTION("""COMPUTED_VALUE"""),"Kedai") -> Kedai | S19: =IFERROR(__xludf.DUMMYFUNCTION("""COMPUTED_VALUE"""),"Temu Roti") -> Temu Roti | T19: =IFERROR(__xludf.DUMMYFUNCTION("""COMPUTED_VALUE"""),"Owner") -> Owner | X19: =IFERROR(__xludf.DUMMYFUNCTION("""COMPUTED_VALUE"""),"Closed") -> Closed
A20: 29/09/2024 17:44,2-9559,Sale,Kudapan,10015,Tahu Lada Garam,,,1.000,25238.00,0.00,25238.00,0.00,25238.00,1262.00,Dine In,Kedai,Temu Roti,Owner,,,,Closed | B20: =IFERROR(__xludf.DUMMYFUNCTION("SPLIT(A20,"","",0,0)"),45564.73888888889) -> 45564.739 | C20: =IFERROR(__xludf.DUMMYFUNCTION("""COMPUTED_VALUE"""),2797425.0) -> 2797425 | D20: =IFERROR(__xludf.DUMMYFUNCTION("""COMPUTED_VALUE"""),"Sale") -> Sale | E20: =IFERROR(__xludf.DUMMYFUNCTION("""COMPUTED_VALUE"""),"Kudapan") -> Kudapan | F20: =IFERROR(__xludf.DUMMYFUNCTION("""COMPUTED_VALUE"""),10015.0) -> 10015 | G20: =IFERROR(__xludf.DUMMYFUNCTION("""COMPUTED_VALUE"""),"Tahu Lada Garam") -> Tahu Lada Garam | J20: =IFERROR(__xludf.DUMMYFUNCTION("""COMPUTED_VALUE"""),1.0) -> 1 | K20: =IFERROR(__xludf.DUMMYFUNCTION("""COMPUTED_VALUE"""),25238.0) -> 25238 | L20: =IFERROR(__xludf.DUMMYFUNCTION("""COMPUTED_VALUE"""),0.0) -> 0 | M20: =IFERROR(__xludf.DUMMYFUNCTION("""COMPUTED_VALUE"""),25238.0) -> 25238 | N20: =IFERROR(__xludf.DUMMYFUNCTION("""COMPUTED_VALUE"""),0.0) -> 0 | O20: =IFERROR(__xludf.DUMMYFUNCTION("""COMPUTED_VALUE"""),25238.0) -> 25238 | P20: =IFERROR(__xludf.DUMMYFUNCTION("""COMPUTED_VALUE"""),1262.0) -> 1262 | Q20: =IFERROR(__xludf.DUMMYFUNCTION("""COMPUTED_VALUE"""),"Dine In") -> Dine In | R20: =IFERROR(__xludf.DUMMYFUNCTION("""COMPUTED_VALUE"""),"Kedai") -> Kedai | S20: =IFERROR(__xludf.DUMMYFUNCTION("""COMPUTED_VALUE"""),"Temu Roti") -> Temu Roti | T20: =IFERROR(__xludf.DUMMYFUNCTION("""COMPUTED_VALUE"""),"Owner") -> Owner | X20: =IFERROR(__xludf.DUMMYFUNCTION("""COMPUTED_VALUE"""),"Closed") -> Closed
A21: 29/09/2024 17:40,2-9558,Sale,Minuman,10128,Es Kopi Susu,,,1.000,23333.00,0.00,23333.00,0.00,23333.00,1167.00,Dine In,Kedai,Temu Roti,Owner,,,,Closed | B21: =IFERROR(__xludf.DUMMYFUNCTION("SPLIT(A21,"","",0,0)"),45564.73611111111) -> 45564.736 | C21: =IFERROR(__xludf.DUMMYFUNCTION("""COMPUTED_VALUE"""),2797060.0) -> 2797060 | D21: =IFERROR(__xludf.DUMMYFUNCTION("""COMPUTED_VALUE"""),"Sale") -> Sale | E21: =IFERROR(__xludf.DUMMYFUNCTION("""COMPUTED_VALUE"""),"Minuman") -> Minuman | F21: =IFERROR(__xludf.DUMMYFUNCTION("""COMPUTED_VALUE"""),10128.0) -> 10128 | G21: =IFERROR(__xludf.DUMMYFUNCTION("""COMPUTED_VALUE"""),"Es Kopi Susu") -> Es Kopi Susu | J21: =IFERROR(__xludf.DUMMYFUNCTION("""COMPUTED_VALUE"""),1.0) -> 1 | K21: =IFERROR(__xludf.DUMMYFUNCTION("""COMPUTED_VALUE"""),23333.0) -> 23333 | L21: =IFERROR(__xludf.DUMMYFUNCTION("""COMPUTED_VALUE"""),0.0) -> 0 | M21: =IFERROR(__xludf.DUMMYFUNCTION("""COMPUTED_VALUE"""),23333.0) -> 23333 | N21: =IFERROR(__xludf.DUMMYFUNCTION("""COMPUTED_VALUE"""),0.0) -> 0 | O21: =IFERROR(__xludf.DUMMYFUNCTION("""COMPUTED_VALUE"""),23333.0) -> 23333 | P21: =IFERROR(__xludf.DUMMYFUNCTION("""COMPUTED_VALUE"""),1167.0) -> 1167 | Q21: =IFERROR(__xludf.DUMMYFUNCTION("""COMPUTED_VALUE"""),"Dine In") -> Dine In | R21: =IFERROR(__xludf.DUMMYFUNCTION("""COMPUTED_VALUE"""),"Kedai") -> Kedai | S21: =IFERROR(__xludf.DUMMYFUNCTION("""COMPUTED_VALUE"""),"Temu Roti") -> Temu Roti | T21: =IFERROR(__xludf.DUMMYFUNCTION("""COMPUTED_VALUE"""),"Owner") -> Owner | X21: =IFERROR(__xludf.DUMMYFUNCTION("""COMPUTED_VALUE"""),"Closed") -> Closed
A22: 29/09/2024 17:40,2-9558,Sale,Roti,10000,Roti Bawang Saus Keju,,,1.000,29524.00,0.00,29524.00,0.00,29524.00,1476.00,Dine In,Kedai,Temu Roti,Owner,,,,Closed | B22: =IFERROR(__xludf.DUMMYFUNCTION("SPLIT(A22,"","",0,0)"),45564.73611111111) -> 45564.736 | C22: =IFERROR(__xludf.DUMMYFUNCTION("""COMPUTED_VALUE"""),2797060.0) -> 2797060 | D22: =IFERROR(__xludf.DUMMYFUNCTION("""COMPUTED_VALUE"""),"Sale") -> Sale | E22: =IFERROR(__xludf.DUMMYFUNCTION("""COMPUTED_VALUE"""),"Roti") -> Roti | F22: =IFERROR(__xludf.DUMMYFUNCTION("""COMPUTED_VALUE"""),10000.0) -> 10000 | G22: =IFERROR(__xludf.DUMMYFUNCTION("""COMPUTED_VALUE"""),"Roti Bawang Saus Keju") -> Roti Bawang Saus Keju | J22: =IFERROR(__xludf.DUMMYFUNCTION("""COMPUTED_VALUE"""),1.0) -> 1 | K22: =IFERROR(__xludf.DUMMYFUNCTION("""COMPUTED_VALUE"""),29524.0) -> 29524 | L22: =IFERROR(__xludf.DUMMYFUNCTION("""COMPUTED_VALUE"""),0.0) -> 0 | M22: =IFERROR(__xludf.DUMMYFUNCTION("""COMPUTED_VALUE"""),29524.0) -> 29524 | N22: =IFERROR(__xludf.DUMMYFUNCTION("""COMPUTED_VALUE"""),0.0) -> 0 | O22: =IFERROR(__xludf.DUMMYFUNCTION("""COMPUTED_VALUE"""),29524.0) -> 29524 | P22: =IFERROR(__xludf.DUMMYFUNCTION("""COMPUTED_VALUE"""),1476.0) -> 1476 | Q22: =IFERROR(__xludf.DUMMYFUNCTION("""COMPUTED_VALUE"""),"Dine In") -> Dine In | R22: =IFERROR(__xludf.DUMMYFUNCTION("""COMPUTED_VALUE"""),"Kedai") -> Kedai | S22: =IFERROR(__xludf.DUMMYFUNCTION("""COMPUTED_VALUE"""),"Temu Roti") -> Temu Roti | T22: =IFERROR(__xludf.DUMMYFUNCTION("""COMPUTED_VALUE"""),"Owner") -> Owner | X22: =IFERROR(__xludf.DUMMYFUNCTION("""COMPUTED_VALUE"""),"Closed") -> Closed
A23: 29/09/2024 17:40,2-9558,Sale,Minuman,10117,Teh Manis Dingin,,,1.000,14286.00,0.00,14286.00,0.00,14286.00,714.00,Dine In,Kedai,Temu Roti,Owner,,,,Closed | B23: =IFERROR(__xludf.DUMMYFUNCTION("SPLIT(A23,"","",0,0)"),45564.73611111111) -> 45564.736 | C23: =IFERROR(__xludf.DUMMYFUNCTION("""COMPUTED_VALUE"""),2797060.0) -> 2797060 | D23: =IFERROR(__xludf.DUMMYFUNCTION("""COMPUTED_VALUE"""),"Sale") -> Sale | E23: =IFERROR(__xludf.DUMMYFUNCTION("""COMPUTED_VALUE"""),"Minuman") -> Minuman | F23: =IFERROR(__xludf.DUMMYFUNCTION("""COMPUTED_VALUE"""),10117.0) -> 10117 | G23: =IFERROR(__xludf.DUMMYFUNCTION("""COMPUTED_VALUE"""),"Teh Manis Dingin") -> Teh Manis Dingin | J23: =IFERROR(__xludf.DUMMYFUNCTION("""COMPUTED_VALUE"""),1.0) -> 1 | K23: =IFERROR(__xludf.DUMMYFUNCTION("""COMPUTED_VALUE"""),14286.0) -> 14286 | L23: =IFERROR(__xludf.DUMMYFUNCTION("""COMPUTED_VALUE"""),0.0) -> 0 | M23: =IFERROR(__xludf.DUMMYFUNCTION("""COMPUTED_VALUE"""),14286.0) -> 14286 | N23: =IFERROR(__xludf.DUMMYFUNCTION("""COMPUTED_VALUE"""),0.0) -> 0 | O23: =IFERROR(__xludf.DUMMYFUNCTION("""COMPUTED_VALUE"""),14286.0) -> 14286 | P23: =IFERROR(__xludf.DUMMYFUNCTION("""COMPUTED_VALUE"""),714.0) -> 714 | Q23: =IFERROR(__xludf.DUMMYFUNCTION("""COMPUTED_VALUE"""),"Dine In") -> Dine In | R23: =IFERROR(__xludf.DUMMYFUNCTION("""COMPUTED_VALUE"""),"Kedai") -> Kedai | S23: =IFERROR(__xludf.DUMMYFUNCTION("""COMPUTED_VALUE"""),"Temu Roti") -> Temu Roti | T23: =IFERROR(__xludf.DUMMYFUNCTION("""COMPUTED_VALUE"""),"Owner") -> Owner | X23: =IFERROR(__xludf.DUMMYFUNCTION("""COMPUTED_VALUE"""),"Closed") -> Closed
A24: 29/09/2024 17:34,2-9557,Sale,Roti,10000,Roti Bawang Saus Keju,,,1.000,29524.00,0.00,29524.00,0.00,29524.00,1476.00,Dine In,Kedai,Temu Roti,Owner,,,,Closed | B24: =IFERROR(__xludf.DUMMYFUNCTION("SPLIT(A24,"","",0,0)"),45564.731944444444) -> 45564.732 | C24: =IFERROR(__xludf.DUMMYFUNCTION("""COMPUTED_VALUE"""),2796695.0) -> 2796695 | D24: =IFERROR(__xludf.DUMMYFUNCTION("""COMPUTED_VALUE"""),"Sale") -> Sale | E24: =IFERROR(__xludf.DUMMYFUNCTION("""COMPUTED_VALUE"""),"Roti") -> Roti | F24: =IFERROR(__xludf.DUMMYFUNCTION("""COMPUTED_VALUE"""),10000.0) -> 10000 | G24: =IFERROR(__xludf.DUMMYFUNCTION("""COMPUTED_VALUE"""),"Roti Bawang Saus Keju") -> Roti Bawang Saus Keju | J24: =IFERROR(__xludf.DUMMYFUNCTION("""COMPUTED_VALUE"""),1.0) -> 1 | K24: =IFERROR(__xludf.DUMMYFUNCTION("""COMPUTED_VALUE"""),29524.0) -> 29524 | L24: =IFERROR(__xludf.DUMMYFUNCTION("""COMPUTED_VALUE"""),0.0) -> 0 | M24: =IFERROR(__xludf.DUMMYFUNCTION("""COMPUTED_VALUE"""),29524.0) -> 29524 | N24: =IFERROR(__xludf.DUMMYFUNCTION("""COMPUTED_VALUE"""),0.0) -> 0 | O24: =IFERROR(__xludf.DUMMYFUNCTION("""COMPUTED_VALUE"""),29524.0) -> 29524 | P24: =IFERROR(__xludf.DUMMYFUNCTION("""COMPUTED_VALUE"""),1476.0) -> 1476 | Q24: =IFERROR(__xludf.DUMMYFUNCTION("""COMPUTED_VALUE"""),"Dine In") -> Dine In | R24: =IFERROR(__xludf.DUMMYFUNCTION("""COMPUTED_VALUE"""),"Kedai") -> Kedai | S24: =IFERROR(__xludf.DUMMYFUNCTION("""COMPUTED_VALUE"""),"Temu Roti") -> Temu Roti | T24: =IFERROR(__xludf.DUMMYFUNCTION("""COMPUTED_VALUE"""),"Owner") -> Owner | X24: =IFERROR(__xludf.DUMMYFUNCTION("""COMPUTED_VALUE"""),"Closed") -> Closed
A25: 29/09/2024 17:34,2-9557,Sale,Minuman,10120,Lemon Tea Panas,,,1.000,19524.00,0.00,19524.00,0.00,19524.00,976.00,Dine In,Kedai,Temu Roti,Owner,,,,Closed | B25: =IFERROR(__xludf.DUMMYFUNCTION("SPLIT(A25,"","",0,0)"),45564.731944444444) -> 45564.732 | C25: =IFERROR(__xludf.DUMMYFUNCTION("""COMPUTED_VALUE"""),2796695.0) -> 2796695 | D25: =IFERROR(__xludf.DUMMYFUNCTION("""COMPUTED_VALUE"""),"Sale") -> Sale | E25: =IFERROR(__xludf.DUMMYFUNCTION("""COMPUTED_VALUE"""),"Minuman") -> Minuman | F25: =IFERROR(__xludf.DUMMYFUNCTION("""COMPUTED_VALUE"""),10120.0) -> 10120 | G25: =IFERROR(__xludf.DUMMYFUNCTION("""COMPUTED_VALUE"""),"Lemon Tea Panas") -> Lemon Tea Panas | J25: =IFERROR(__xludf.DUMMYFUNCTION("""COMPUTED_VALUE"""),1.0) -> 1 | K25: =IFERROR(__xludf.DUMMYFUNCTION("""COMPUTED_VALUE"""),19524.0) -> 19524 | L25: =IFERROR(__xludf.DUMMYFUNCTION("""COMPUTED_VALUE"""),0.0) -> 0 | M25: =IFERROR(__xludf.DUMMYFUNCTION("""COMPUTED_VALUE"""),19524.0) -> 19524 | N25: =IFERROR(__xludf.DUMMYFUNCTION("""COMPUTED_VALUE"""),0.0) -> 0 | O25: =IFERROR(__xludf.DUMMYFUNCTION("""COMPUTED_VALUE"""),19524.0) -> 19524 | P25: =IFERROR(__xludf.DUMMYFUNCTION("""COMPUTED_VALUE"""),976.0) -> 976 | Q25: =IFERROR(__xludf.DUMMYFUNCTION("""COMPUTED_VALUE"""),"Dine In") -> Dine In | R25: =IFERROR(__xludf.DUMMYFUNCTION("""COMPUTED_VALUE"""),"Kedai") -> Kedai | S25: =IFERROR(__xludf.DUMMYFUNCTION("""COMPUTED_VALUE"""),"Temu Roti") -> Temu Roti | T25: =IFERROR(__xludf.DUMMYFUNCTION("""COMPUTED_VALUE"""),"Owner") -> Owner | X25: =IFERROR(__xludf.DUMMYFUNCTION("""COMPUTED_VALUE"""),"Closed") -> Closed
A26: 29/09/2024 17:34,2-9557,Sale,Minuman,10122,Rempah Madu Panas,,,1.000,21905.00,0.00,21905.00,0.00,21905.00,1096.00,Dine In,Kedai,Temu Roti,Owner,,,,Closed | B26: =IFERROR(__xludf.DUMMYFUNCTION("SPLIT(A26,"","",0,0)"),45564.731944444444) -> 45564.732 | C26: =IFERROR(__xludf.DUMMYFUNCTION("""COMPUTED_VALUE"""),2796695.0) -> 2796695 | D26: =IFERROR(__xludf.DUMMYFUNCTION("""COMPUTED_VALUE"""),"Sale") -> Sale | E26: =IFERROR(__xludf.DUMMYFUNCTION("""COMPUTED_VALUE"""),"Minuman") -> Minuman | F26: =IFERROR(__xludf.DUMMYFUNCTION("""COMPUTED_VALUE"""),10122.0) -> 10122 | G26: =IFERROR(__xludf.DUMMYFUNCTION("""COMPUTED_VALUE"""),"Rempah Madu Panas") -> Rempah Madu Panas | J26: =IFERROR(__xludf.DUMMYFUNCTION("""COMPUTED_VALUE"""),1.0) -> 1 | K26: =IFERROR(__xludf.DUMMYFUNCTION("""COMPUTED_VALUE"""),21905.0) -> 21905 | L26: =IFERROR(__xludf.DUMMYFUNCTION("""COMPUTED_VALUE"""),0.0) -> 0 | M26: =IFERROR(__xludf.DUMMYFUNCTION("""COMPUTED_VALUE"""),21905.0) -> 21905 | N26: =IFERROR(__xludf.DUMMYFUNCTION("""COMPUTED_VALUE"""),0.0) -> 0 | O26: =IFERROR(__xludf.DUMMYFUNCTION("""COMPUTED_VALUE"""),21905.0) -> 21905 | P26: =IFERROR(__xludf.DUMMYFUNCTION("""COMPUTED_VALUE"""),1096.0) -> 1096 | Q26: =IFERROR(__xludf.DUMMYFUNCTION("""COMPUTED_VALUE"""),"Dine In") -> Dine In | R26: =IFERROR(__xludf.DUMMYFUNCTION("""COMPUTED_VALUE"""),"Kedai") -> Kedai | S26: =IFERROR(__xludf.DUMMYFUNCTION("""COMPUTED_VALUE"""),"Temu Roti") -> Temu Roti | T26: =IFERROR(__xludf.DUMMYFUNCTION("""COMPUTED_VALUE"""),"Owner") -> Owner | X26: =IFERROR(__xludf.DUMMYFUNCTION("""COMPUTED_VALUE"""),"Closed") -> Closed
A27: 29/09/2024 17:30,2-9556,Sale,Minuman,10128,Es Kopi Susu,,,1.000,23333.00,0.00,23333.00,0.00,23333.00,1167.00,Dine In,Kedai,Temu Roti,Owner,,,,Closed | B27: =IFERROR(__xludf.DUMMYFUNCTION("SPLIT(A27,"","",0,0)"),45564.729166666664) -> 45564.729 | C27: =IFERROR(__xludf.DUMMYFUNCTION("""COMPUTED_VALUE"""),2796329.0) -> 2796329 | D27: =IFERROR(__xludf.DUMMYFUNCTION("""COMPUTED_VALUE"""),"Sale") -> Sale | E27: =IFERROR(__xludf.DUMMYFUNCTION("""COMPUTED_VALUE"""),"Minuman") -> Minuman | F27: =IFERROR(__xludf.DUMMYFUNCTION("""COMPUTED_VALUE"""),10128.0) -> 10128 | G27: =IFERROR(__xludf.DUMMYFUNCTION("""COMPUTED_VALUE"""),"Es Kopi Susu") -> Es Kopi Susu | J27: =IFERROR(__xludf.DUMMYFUNCTION("""COMPUTED_VALUE"""),1.0) -> 1 | K27: =IFERROR(__xludf.DUMMYFUNCTION("""COMPUTED_VALUE"""),23333.0) -> 23333 | L27: =IFERROR(__xludf.DUMMYFUNCTION("""COMPUTED_VALUE"""),0.0) -> 0 | M27: =IFERROR(__xludf.DUMMYFUNCTION("""COMPUTED_VALUE"""),23333.0) -> 23333 | N27: =IFERROR(__xludf.DUMMYFUNCTION("""COMPUTED_VALUE"""),0.0) -> 0 | O27: =IFERROR(__xludf.DUMMYFUNCTION("""COMPUTED_VALUE"""),23333.0) -> 23333 | P27: =IFERROR(__xludf.DUMMYFUNCTION("""COMPUTED_VALUE"""),1167.0) -> 1167 | Q27: =IFERROR(__xludf.DUMMYFUNCTION("""COMPUTED_VALUE"""),"Dine In") -> Dine In | R27: =IFERROR(__xludf.DUMMYFUNCTION("""COMPUTED_VALUE"""),"Kedai") -> Kedai | S27: =IFERROR(__xludf.DUMMYFUNCTION("""COMPUTED_VALUE"""),"Temu Roti") -> Temu Roti | T27: =IFERROR(__xludf.DUMMYFUNCTION("""COMPUTED_VALUE"""),"Owner") -> Owner | X27: =IFERROR(__xludf.DUMMYFUNCTION("""COMPUTED_VALUE"""),"Closed") -> Closed
A28: 29/09/2024 17:30,2-9556,Sale,Roti,10002,Roti Cranberry,,,1.000,18571.00,0.00,18571.00,0.00,18571.00,928.00,Dine In,Kedai,Temu Roti,Owner,,,,Closed | B28: =IFERROR(__xludf.DUMMYFUNCTION("SPLIT(A28,"","",0,0)"),45564.729166666664) -> 45564.729 | C28: =IFERROR(__xludf.DUMMYFUNCTION("""COMPUTED_VALUE"""),2796329.0) -> 2796329 | D28: =IFERROR(__xludf.DUMMYFUNCTION("""COMPUTED_VALUE"""),"Sale") -> Sale | E28: =IFERROR(__xludf.DUMMYFUNCTION("""COMPUTED_VALUE"""),"Roti") -> Roti | F28: =IFERROR(__xludf.DUMMYFUNCTION("""COMPUTED_VALUE"""),10002.0) -> 10002 | G28: =IFERROR(__xludf.DUMMYFUNCTION("""COMPUTED_VALUE"""),"Roti Cranberry") -> Roti Cranberry | J28: =IFERROR(__xludf.DUMMYFUNCTION("""COMPUTED_VALUE"""),1.0) -> 1 | K28: =IFERROR(__xludf.DUMMYFUNCTION("""COMPUTED_VALUE"""),18571.0) -> 18571 | L28: =IFERROR(__xludf.DUMMYFUNCTION("""COMPUTED_VALUE"""),0.0) -> 0 | M28: =IFERROR(__xludf.DUMMYFUNCTION("""COMPUTED_VALUE"""),18571.0) -> 18571 | N28: =IFERROR(__xludf.DUMMYFUNCTION("""COMPUTED_VALUE"""),0.0) -> 0 | O28: =IFERROR(__xludf.DUMMYFUNCTION("""COMPUTED_VALUE"""),18571.0) -> 18571 | P28: =IFERROR(__xludf.DUMMYFUNCTION("""COMPUTED_VALUE"""),928.0) -> 928 | Q28: =IFERROR(__xludf.DUMMYFUNCTION("""COMPUTED_VALUE"""),"Dine In") -> Dine In | R28: =IFERROR(__xludf.DUMMYFUNCTION("""COMPUTED_VALUE"""),"Kedai") -> Kedai | S28: =IFERROR(__xludf.DUMMYFUNCTION("""COMPUTED_VALUE"""),"Temu Roti") -> Temu Roti | T28: =IFERROR(__xludf.DUMMYFUNCTION("""COMPUTED_VALUE"""),"Owner") -> Owner | X28: =IFERROR(__xludf.DUMMYFUNCTION("""COMPUTED_VALUE"""),"Closed") -> Closed
A29: 29/09/2024 17:15,2-9555,Sale,Roti,10000,Roti Bawang Saus Keju,,,1.000,29524.00,0.00,29524.00,0.00,29524.00,1476.00,Dine In,Kedai,Temu Roti,Owner,,,,Closed | B29: =IFERROR(__xludf.DUMMYFUNCTION("SPLIT(A29,"","",0,0)"),45564.71875) -> 45564.719 | C29: =IFERROR(__xludf.DUMMYFUNCTION("""COMPUTED_VALUE"""),2795964.0) -> 2795964 | D29: =IFERROR(__xludf.DUMMYFUNCTION("""COMPUTED_VALUE"""),"Sale") -> Sale | E29: =IFERROR(__xludf.DUMMYFUNCTION("""COMPUTED_VALUE"""),"Roti") -> Roti | F29: =IFERROR(__xludf.DUMMYFUNCTION("""COMPUTED_VALUE"""),10000.0) -> 10000 | G29: =IFERROR(__xludf.DUMMYFUNCTION("""COMPUTED_VALUE"""),"Roti Bawang Saus Keju") -> Roti Bawang Saus Keju | J29: =IFERROR(__xludf.DUMMYFUNCTION("""COMPUTED_VALUE"""),1.0) -> 1 | K29: =IFERROR(__xludf.DUMMYFUNCTION("""COMPUTED_VALUE"""),29524.0) -> 29524 | L29: =IFERROR(__xludf.DUMMYFUNCTION("""COMPUTED_VALUE"""),0.0) -> 0 | M29: =IFERROR(__xludf.DUMMYFUNCTION("""COMPUTED_VALUE"""),29524.0) -> 29524 | N29: =IFERROR(__xludf.DUMMYFUNCTION("""COMPUTED_VALUE"""),0.0) -> 0 | O29: =IFERROR(__xludf.DUMMYFUNCTION("""COMPUTED_VALUE"""),29524.0) -> 29524 | P29: =IFERROR(__xludf.DUMMYFUNCTION("""COMPUTED_VALUE"""),1476.0) -> 1476 | Q29: =IFERROR(__xludf.DUMMYFUNCTION("""COMPUTED_VALUE"""),"Dine In") -> Dine In | R29: =IFERROR(__xludf.DUMMYFUNCTION("""COMPUTED_VALUE"""),"Kedai") -> Kedai | S29: =IFERROR(__xludf.DUMMYFUNCTION("""COMPUTED_VALUE"""),"Temu Roti") -> Temu Roti | T29: =IFERROR(__xludf.DUMMYFUNCTION("""COMPUTED_VALUE"""),"Owner") -> Owner | X29: =IFERROR(__xludf.DUMMYFUNCTION("""COMPUTED_VALUE"""),"Closed") -> Closed
A30: 29/09/2024 17:15,2-9555,Sale,Minuman,10013,Kopi cur,,,1.000,23333.00,0.00,23333.00,0.00,23333.00,1167.00,Dine In,Kedai,Temu Roti,Owner,,,,Closed | B30: =IFERROR(__xludf.DUMMYFUNCTION("SPLIT(A30,"","",0,0)"),45564.71875) -> 45564.719 | C30: =IFERROR(__xludf.DUMMYFUNCTION("""COMPUTED_VALUE"""),2795964.0) -> 2795964 | D30: =IFERROR(__xludf.DUMMYFUNCTION("""COMPUTED_VALUE"""),"Sale") -> Sale | E30: =IFERROR(__xludf.DUMMYFUNCTION("""COMPUTED_VALUE"""),"Minuman") -> Minuman | F30: =IFERROR(__xludf.DUMMYFUNCTION("""COMPUTED_VALUE"""),10013.0) -> 10013 | G30: =IFERROR(__xludf.DUMMYFUNCTION("""COMPUTED_VALUE"""),"Kopi cur") -> Kopi cur | J30: =IFERROR(__xludf.DUMMYFUNCTION("""COMPUTED_VALUE"""),1.0) -> 1 | K30: =IFERROR(__xludf.DUMMYFUNCTION("""COMPUTED_VALUE"""),23333.0) -> 23333 | L30: =IFERROR(__xludf.DUMMYFUNCTION("""COMPUTED_VALUE"""),0.0) -> 0 | M30: =IFERROR(__xludf.DUMMYFUNCTION("""COMPUTED_VALUE"""),23333.0) -> 23333 | N30: =IFERROR(__xludf.DUMMYFUNCTION("""COMPUTED_VALUE"""),0.0) -> 0 | O30: =IFERROR(__xludf.DUMMYFUNCTION("""COMPUTED_VALUE"""),23333.0) -> 23333 | P30: =IFERROR(__xludf.DUMMYFUNCTION("""COMPUTED_VALUE"""),1167.0) -> 1167 | Q30: =IFERROR(__xludf.DUMMYFUNCTION("""COMPUTED_VALUE"""),"Dine In") -> Dine In | R30: =IFERROR(__xludf.DUMMYFUNCTION("""COMPUTED_VALUE"""),"Kedai") -> Kedai | S30: =IFERROR(__xludf.DUMMYFUNCTION("""COMPUTED_VALUE"""),"Temu Roti") -> Temu Roti | T30: =IFERROR(__xludf.DUMMYFUNCTION("""COMPUTED_VALUE"""),"Owner") -> Owner | X30: =IFERROR(__xludf.DUMMYFUNCTION("""COMPUTED_VALUE"""),"Closed") -> Closed
A31: 29/09/2024 17:15,2-9555,Sale,Minuman,10127,Kopi Tubruk Panas,,,1.000,18571.00,0.00,18571.00,0.00,18571.00,928.00,Dine In,Kedai,Temu Roti,Owner,,,,Closed | B31: =IFERROR(__xludf.DUMMYFUNCTION("SPLIT(A31,"","",0,0)"),45564.71875) -> 45564.719 | C31: =IFERROR(__xludf.DUMMYFUNCTION("""COMPUTED_VALUE"""),2795964.0) -> 2795964 | D31: =IFERROR(__xludf.DUMMYFUNCTION("""COMPUTED_VALUE"""),"Sale") -> Sale | E31: =IFERROR(__xludf.DUMMYFUNCTION("""COMPUTED_VALUE"""),"Minuman") -> Minuman | F31: =IFERROR(__xludf.DUMMYFUNCTION("""COMPUTED_VALUE"""),10127.0) -> 10127 | G31: =IFERROR(__xludf.DUMMYFUNCTION("""COMPUTED_VALUE"""),"Kopi Tubruk Panas") -> Kopi Tubruk Panas | J31: =IFERROR(__xludf.DUMMYFUNCTION("""COMPUTED_VALUE"""),1.0) -> 1 | K31: =IFERROR(__xludf.DUMMYFUNCTION("""COMPUTED_VALUE"""),18571.0) -> 18571 | L31: =IFERROR(__xludf.DUMMYFUNCTION("""COMPUTED_VALUE"""),0.0) -> 0 | M31: =IFERROR(__xludf.DUMMYFUNCTION("""COMPUTED_VALUE"""),18571.0) -> 18571 | N31: =IFERROR(__xludf.DUMMYFUNCTION("""COMPUTED_VALUE"""),0.0) -> 0 | O31: =IFERROR(__xludf.DUMMYFUNCTION("""COMPUTED_VALUE"""),18571.0) -> 18571 | P31: =IFERROR(__xludf.DUMMYFUNCTION("""COMPUTED_VALUE"""),928.0) -> 928 | Q31: =IFERROR(__xludf.DUMMYFUNCTION("""COMPUTED_VALUE"""),"Dine In") -> Dine In | R31: =IFERROR(__xludf.DUMMYFUNCTION("""COMPUTED_VALUE"""),"Kedai") -> Kedai | S31: =IFERROR(__xludf.DUMMYFUNCTION("""COMPUTED_VALUE"""),"Temu Roti") -> Temu Roti | T31: =IFERROR(__xludf.DUMMYFUNCTION("""COMPUTED_VALUE"""),"Owner") -> Owner | X31: =IFERROR(__xludf.DUMMYFUNCTION("""COMPUTED_VALUE"""),"Closed") -> Closed
A32: 29/09/2024 17:15,2-9555,Sale,Minuman,10070,Wedang laut,,,1.000,24762.00,0.00,24762.00,0.00,24762.00,1239.00,Dine In,Kedai,Temu Roti,Owner,,,,Closed | B32: =IFERROR(__xludf.DUMMYFUNCTION("SPLIT(A32,"","",0,0)"),45564.71875) -> 45564.719 | C32: =IFERROR(__xludf.DUMMYFUNCTION("""COMPUTED_VALUE"""),2795964.0) -> 2795964 | D32: =IFERROR(__xludf.DUMMYFUNCTION("""COMPUTED_VALUE"""),"Sale") -> Sale | E32: =IFERROR(__xludf.DUMMYFUNCTION("""COMPUTED_VALUE"""),"Minuman") -> Minuman | F32: =IFERROR(__xludf.DUMMYFUNCTION("""COMPUTED_VALUE"""),10070.0) -> 10070 | G32: =IFERROR(__xludf.DUMMYFUNCTION("""COMPUTED_VALUE"""),"Wedang laut") -> Wedang laut | J32: =IFERROR(__xludf.DUMMYFUNCTION("""COMPUTED_VALUE"""),1.0) -> 1 | K32: =IFERROR(__xludf.DUMMYFUNCTION("""COMPUTED_VALUE"""),24762.0) -> 24762 | L32: =IFERROR(__xludf.DUMMYFUNCTION("""COMPUTED_VALUE"""),0.0) -> 0 | M32: =IFERROR(__xludf.DUMMYFUNCTION("""COMPUTED_VALUE"""),24762.0) -> 24762 | N32: =IFERROR(__xludf.DUMMYFUNCTION("""COMPUTED_VALUE"""),0.0) -> 0 | O32: =IFERROR(__xludf.DUMMYFUNCTION("""COMPUTED_VALUE"""),24762.0) -> 24762 | P32: =IFERROR(__xludf.DUMMYFUNCTION("""COMPUTED_VALUE"""),1239.0) -> 1239 | Q32: =IFERROR(__xludf.DUMMYFUNCTION("""COMPUTED_VALUE"""),"Dine In") -> Dine In | R32: =IFERROR(__xludf.DUMMYFUNCTION("""COMPUTED_VALUE"""),"Kedai") -> Kedai | S32: =IFERROR(__xludf.DUMMYFUNCTION("""COMPUTED_VALUE"""),"Temu Roti") -> Temu Roti | T32: =IFERROR(__xludf.DUMMYFUNCTION("""COMPUTED_VALUE"""),"Owner") -> Owner | X32: =IFERROR(__xludf.DUMMYFUNCTION("""COMPUTED_VALUE"""),"Closed") -> Closed
A33: 29/09/2024 17:13,2-9554,Sale,Minuman,10128,Es Kopi Susu,,,1.000,23333.00,0.00,23333.00,0.00,23333.00,1167.00,Dine In,Kedai,Temu Roti,Owner,,,,Closed | B33: =IFERROR(__xludf.DUMMYFUNCTION("SPLIT(A33,"","",0,0)"),45564.717361111114) -> 45564.717 | C33: =IFERROR(__xludf.DUMMYFUNCTION("""COMPUTED_VALUE"""),2795599.0) -> 2795599 | D33: =IFERROR(__xludf.DUMMYFUNCTION("""COMPUTED_VALUE"""),"Sale") -> Sale | E33: =IFERROR(__xludf.DUMMYFUNCTION("""COMPUTED_VALUE"""),"Minuman") -> Minuman | F33: =IFERROR(__xludf.DUMMYFUNCTION("""COMPUTED_VALUE"""),10128.0) -> 10128 | G33: =IFERROR(__xludf.DUMMYFUNCTION("""COMPUTED_VALUE"""),"Es Kopi Susu") -> Es Kopi Susu | J33: =IFERROR(__xludf.DUMMYFUNCTION("""COMPUTED_VALUE"""),1.0) -> 1 | K33: =IFERROR(__xludf.DUMMYFUNCTION("""COMPUTED_VALUE"""),23333.0) -> 23333 | L33: =IFERROR(__xludf.DUMMYFUNCTION("""COMPUTED_VALUE"""),0.0) -> 0 | M33: =IFERROR(__xludf.DUMMYFUNCTION("""COMPUTED_VALUE"""),23333.0) -> 23333 | N33: =IFERROR(__xludf.DUMMYFUNCTION("""COMPUTED_VALUE"""),0.0) -> 0 | O33: =IFERROR(__xludf.DUMMYFUNCTION("""COMPUTED_VALUE"""),23333.0) -> 23333 | P33: =IFERROR(__xludf.DUMMYFUNCTION("""COMPUTED_VALUE"""),1167.0) -> 1167 | Q33: =IFERROR(__xludf.DUMMYFUNCTION("""COMPUTED_VALUE"""),"Dine In") -> Dine In | R33: =IFERROR(__xludf.DUMMYFUNCTION("""COMPUTED_VALUE"""),"Kedai") -> Kedai | S33: =IFERROR(__xludf.DUMMYFUNCTION("""COMPUTED_VALUE"""),"Temu Roti") -> Temu Roti | T33: =IFERROR(__xludf.DUMMYFUNCTION("""COMPUTED_VALUE"""),"Owner") -> Owner | X33: =IFERROR(__xludf.DUMMYFUNCTION("""COMPUTED_VALUE"""),"Closed") -> Closed
A34: 29/09/2024 16:58,2-9553,Sale,Minuman,10128,Es Kopi Susu,,,2.000,46666.00,0.00,46666.00,0.00,46666.00,2333.00,Dine In,Kedai,Temu Roti,Owner,,,,Closed | B34: =IFERROR(__xludf.DUMMYFUNCTION("SPLIT(A34,"","",0,0)"),45564.70694444444) -> 45564.707 | C34: =IFERROR(__xludf.DUMMYFUNCTION("""COMPUTED_VALUE"""),2795234.0) -> 2795234 | D34: =IFERROR(__xludf.DUMMYFUNCTION("""COMPUTED_VALUE"""),"Sale") -> Sale | E34: =IFERROR(__xludf.DUMMYFUNCTION("""COMPUTED_VALUE"""),"Minuman") -> Minuman | F34: =IFERROR(__xludf.DUMMYFUNCTION("""COMPUTED_VALUE"""),10128.0) -> 10128 | G34: =IFERROR(__xludf.DUMMYFUNCTION("""COMPUTED_VALUE"""),"Es Kopi Susu") -> Es Kopi Susu | J34: =IFERROR(__xludf.DUMMYFUNCTION("""COMPUTED_VALUE"""),2.0) -> 2 | K34: =IFERROR(__xludf.DUMMYFUNCTION("""COMPUTED_VALUE"""),46666.0) -> 46666 | L34: =IFERROR(__xludf.DUMMYFUNCTION("""COMPUTED_VALUE"""),0.0) -> 0 | M34: =IFERROR(__xludf.DUMMYFUNCTION("""COMPUTED_VALUE"""),46666.0) -> 46666 | N34: =IFERROR(__xludf.DUMMYFUNCTION("""COMPUTED_VALUE"""),0.0) -> 0 | O34: =IFERROR(__xludf.DUMMYFUNCTION("""COMPUTED_VALUE"""),46666.0) -> 46666 | P34: =IFERROR(__xludf.DUMMYFUNCTION("""COMPUTED_VALUE"""),2333.0) -> 2333 | Q34: =IFERROR(__xludf.DUMMYFUNCTION("""COMPUTED_VALUE"""),"Dine In") -> Dine In | R34: =IFERROR(__xludf.DUMMYFUNCTION("""COMPUTED_VALUE"""),"Kedai") -> Kedai | S34: =IFERROR(__xludf.DUMMYFUNCTION("""COMPUTED_VALUE"""),"Temu Roti") -> Temu Roti | T34: =IFERROR(__xludf.DUMMYFUNCTION("""COMPUTED_VALUE"""),"Owner") -> Owner | X34: =IFERROR(__xludf.DUMMYFUNCTION("""COMPUTED_VALUE"""),"Closed") -> Closed
A35: 29/09/2024 16:47,2-9552,Sale,Minuman,10063,Wedang Bulan,,,1.000,24762.00,0.00,24762.00,0.00,24762.00,1238.00,Dine In,Kedai,Temu Roti,Owner,,,,Closed | B35: =IFERROR(__xludf.DUMMYFUNCTION("SPLIT(A35,"","",0,0)"),45564.69930555556) -> 45564.699 | C35: =IFERROR(__xludf.DUMMYFUNCTION("""COMPUTED_VALUE"""),2794868.0) -> 2794868 | D35: =IFERROR(__xludf.DUMMYFUNCTION("""COMPUTED_VALUE"""),"Sale") -> Sale | E35: =IFERROR(__xludf.DUMMYFUNCTION("""COMPUTED_VALUE"""),"Minuman") -> Minuman | F35: =IFERROR(__xludf.DUMMYFUNCTION("""COMPUTED_VALUE"""),10063.0) -> 10063 | G35: =IFERROR(__xludf.DUMMYFUNCTION("""COMPUTED_VALUE"""),"Wedang Bulan") -> Wedang Bulan | J35: =IFERROR(__xludf.DUMMYFUNCTION("""COMPUTED_VALUE"""),1.0) -> 1 | K35: =IFERROR(__xludf.DUMMYFUNCTION("""COMPUTED_VALUE"""),24762.0) -> 24762 | L35: =IFERROR(__xludf.DUMMYFUNCTION("""COMPUTED_VALUE"""),0.0) -> 0 | M35: =IFERROR(__xludf.DUMMYFUNCTION("""COMPUTED_VALUE"""),24762.0) -> 24762 | N35: =IFERROR(__xludf.DUMMYFUNCTION("""COMPUTED_VALUE"""),0.0) -> 0 | O35: =IFERROR(__xludf.DUMMYFUNCTION("""COMPUTED_VALUE"""),24762.0) -> 24762 | P35: =IFERROR(__xludf.DUMMYFUNCTION("""COMPUTED_VALUE"""),1238.0) -> 1238 | Q35: =IFERROR(__xludf.DUMMYFUNCTION("""COMPUTED_VALUE"""),"Dine In") -> Dine In | R35: =IFERROR(__xludf.DUMMYFUNCTION("""COMPUTED_VALUE"""),"Kedai") -> Kedai | S35: =IFERROR(__xludf.DUMMYFUNCTION("""COMPUTED_VALUE"""),"Temu Roti") -> Temu Roti | T35: =IFERROR(__xludf.DUMMYFUNCTION("""COMPUTED_VALUE"""),"Owner") -> Owner | X35: =IFERROR(__xludf.DUMMYFUNCTION("""COMPUTED_VALUE"""),"Closed") -> Closed
A36: 29/09/2024 16:47,2-9552,Sale,Minuman,10107,Korean Mango Fresh Milk,,,1.000,26667.00,0.00,26667.00,0.00,26667.00,1333.00,Dine In,Kedai,Temu Roti,Owner,,,,Closed | B36: =IFERROR(__xludf.DUMMYFUNCTION("SPLIT(A36,"","",0,0)"),45564.69930555556) -> 45564.699 | C36: =IFERROR(__xludf.DUMMYFUNCTION("""COMPUTED_VALUE"""),2794868.0) -> 2794868 | D36: =IFERROR(__xludf.DUMMYFUNCTION("""COMPUTED_VALUE"""),"Sale") -> Sale | E36: =IFERROR(__xludf.DUMMYFUNCTION("""COMPUTED_VALUE"""),"Minuman") -> Minuman | F36: =IFERROR(__xludf.DUMMYFUNCTION("""COMPUTED_VALUE"""),10107.0) -> 10107 | G36: =IFERROR(__xludf.DUMMYFUNCTION("""COMPUTED_VALUE"""),"Korean Mango Fresh Milk") -> Korean Mango Fresh Milk | J36: =IFERROR(__xludf.DUMMYFUNCTION("""COMPUTED_VALUE"""),1.0) -> 1 | K36: =IFERROR(__xludf.DUMMYFUNCTION("""COMPUTED_VALUE"""),26667.0) -> 26667 | L36: =IFERROR(__xludf.DUMMYFUNCTION("""COMPUTED_VALUE"""),0.0) -> 0 | M36: =IFERROR(__xludf.DUMMYFUNCTION("""COMPUTED_VALUE"""),26667.0) -> 26667 | N36: =IFERROR(__xludf.DUMMYFUNCTION("""COMPUTED_VALUE"""),0.0) -> 0 | O36: =IFERROR(__xludf.DUMMYFUNCTION("""COMPUTED_VALUE"""),26667.0) -> 26667 | P36: =IFERROR(__xludf.DUMMYFUNCTION("""COMPUTED_VALUE"""),1333.0) -> 1333 | Q36: =IFERROR(__xludf.DUMMYFUNCTION("""COMPUTED_VALUE"""),"Dine In") -> Dine In | R36: =IFERROR(__xludf.DUMMYFUNCTION("""COMPUTED_VALUE"""),"Kedai") -> Kedai | S36: =IFERROR(__xludf.DUMMYFUNCTION("""COMPUTED_VALUE"""),"Temu Roti") -> Temu Roti | T36: =IFERROR(__xludf.DUMMYFUNCTION("""COMPUTED_VALUE"""),"Owner") -> Owner | X36: =IFERROR(__xludf.DUMMYFUNCTION("""COMPUTED_VALUE"""),"Closed") -> Closed
